<robot name="arm">

  <material name="blue">
    <color rgba="0 0 0.8 1" />
  </material>
  <material name="red">
    <color rgba="0.8 0 0 1" />
  </material>
  <material name="green">
    <color rgba="0 0.8 0 1" />
  </material>
  <material name="white">
    <color rgba="1 1 1 1" />
  </material>

  <link name="base_link">
    <visual>
      <geometry>
        <box size="0.25 0.25 0.25"/>
      </geometry>
      <material name="white"/>
    </visual>
  </link>

  <link name="elbow0_box">
     <visual>
      <origin xyz="0 0 0"/>
       <geometry>
         <box size="0.25 0.25 0.25"/>
       </geometry>
      <material name="white"/>
     </visual>
  </link>

  <link name="elbow0">
     <visual>
      <origin xyz="0 0 0"/>
       <geometry>
         <cylinder length="0.25" radius="0.1"/>
       </geometry>
      <material name="white"/>
     </visual>
  </link>

  <link name="link1">
    <visual>
      <geometry>
        <cylinder length="1" radius="0.1"/>
      </geometry>
      <material name="white"/>
    </visual>
  </link>

  <link name="link1_box">
    <visual>
      <geometry>
        <box size="0.2 0.2 0.2"/>
      </geometry>
      <material name="white"/>
    </visual>
  </link>

  <link name="elbow1">
     <visual>
      <origin xyz="0 0 0"/>
       <geometry>
         <cylinder length="0.2" radius="0.1"/>
       </geometry>
      <material name="white"/>
     </visual>
  </link>

  <link name="elbow1_box">
    <visual>
      <geometry>
        <box size="0.2 0.2 0.2"/>
      </geometry>
      <material name="white"/>
    </visual>
  </link>

  <link name="link2">
     <visual>
      <origin xyz="0 0 0"/>
      <geometry>
        <cylinder length="0.5" radius="0.1"/>
      </geometry>
      <material name="white"/>
    </visual>
  </link>

  <link name="link2_box">
    <visual>
      <geometry>
        <box size="0.2 0.2 0.2"/>
      </geometry>
      <material name="white"/>
    </visual>
  </link>

  <link name="elbow2">
     <visual>
      <origin xyz="0 0 0"/>
       <geometry>
         <cylinder length="0.2" radius="0.1"/>
       </geometry>
      <material name="white"/>
     </visual>
  </link>

  <link name="elbow2_box">
    <visual>
      <geometry>
        <box size="0.2 0.2 0.2"/>
      </geometry>
      <material name="white"/>
    </visual>
  </link>

  <link name="camera_platform">
    <visual>
      <geometry>
        <box size="0.2 0.1 0.05"/>
      </geometry>
      <material name="blue"/>
    </visual>
  </link>

  <link name="camera">
    <visual>
      <geometry>
        <box size="0.25 0.25 0.25"/>
      </geometry>
      <material name="red"/>
    </visual>
  </link>

  <link name="camera_face">
    <visual>
      <origin rpy="0 0 1.57" />
      <geometry>
        <box size="0.20 0.01 0.2"/>
      </geometry>
      <material name="green"/>
    </visual>
  </link>

  <joint name="joint0" type="continuous">
    <parent link="base_link"/>
    <child link="elbow0"/>
    <origin xyz="0 -0.25 0" rpy="1.57 0 0" />
    <axis xyz="0 0 1"/>
  </joint>

  <joint name="elbow0_box_joint" type="fixed">
    <parent link="elbow0"/>
    <origin xyz="0 0 0.25" rpy="0 0 0" />
    <child link="elbow0_box"/>
  </joint>

  <joint name="elbow0_joint" type="fixed">
    <parent link="elbow0_box"/>
    <child link="link1"/>
    <origin xyz="0 0.625 0" rpy="-1.57 0 0" />
  </joint> 

  <joint name="link1_box_joint" type="fixed">
    <parent link="link1"/>
    <child link="link1_box"/>
    <origin xyz="0 0 0.6" rpy="0 0 0"/>
  </joint> 
 
  <joint name="joint1" type="continuous">
    <parent link="link1_box"/>
    <child link="elbow1"/>
    <origin xyz="0 -0.2 0" rpy="1.57 0 0" />
    <axis xyz="0 0 1"/>
  </joint>

  <joint name="elbow1_box_joint" type="fixed">
    <parent link="elbow1"/>
    <child link="elbow1_box"/>
    <origin xyz="0 0 0.2" rpy="-1.57 0 0"/>
  </joint> 
 
  <joint name="elbow1_joint" type="fixed">
    <parent link="elbow1_box"/>
    <child link="link2"/>
    <origin xyz="0 0 0.35" rpy="0 0 0"/>
  </joint> 

  <joint name="link2_box_joint" type="fixed">
    <parent link="link2"/>
    <child link="link2_box"/>
    <origin xyz="0 0 0.35" rpy="0 0 0" />
  </joint>

  <joint name="joint2" type="continuous">
    <parent link="link2_box"/>
    <child link="elbow2"/>
    <origin xyz="0 0.2 0" rpy="1.57 0 0" />
    <axis xyz="0 0 1"/>
  </joint>

  <joint name="elbow2_box_joint" type="fixed">
    <parent link="elbow2"/>
    <child link="elbow2_box"/>
    <origin xyz="0 0 -0.2" rpy="0 0 0" />
  </joint>

  <joint name="camera_platform_joint" type="fixed">
    <parent link="elbow2_box"/>
    <child link="camera_platform"/>
    <origin xyz="0 0.125 0" rpy="-1.57 -1.57 0" />
  </joint>

  <joint name="joint3" type="continuous">
    <parent link="camera_platform"/>
    <child link="camera"/>
    <origin xyz="0 0 0.15" rpy="0 0 0" />
    <axis xyz="0 0 1"/>
  </joint>

  <joint name="camera_face_joint" type="fixed">
    <parent link="camera"/>
    <child link="camera_face"/>
    <origin xyz="0 0.125 0" rpy="0 0 1.57" />
  </joint>

</robot>
